Workbook

Sheet Executive Summary
A1: MART INVENTORY & VALUATION DASHBOARD
A3: Automated POS Inventory Classification & Category Breakdown
A4: Total SKUs | B4: Total Stock Units | C4: Total Inventory Cost | D4: Total Retail Value | E4: Total Potential Profit | F4: Overall Margin %
A5: =COUNTA('Inventory (Sorted)'!A4:A730) | B5: =SUM('Inventory (Sorted)'!H4:H730) | C5: =SUM('Inventory (Sorted)'!I4:I730) | D5: =SUM('Inventory (Sorted)'!J4:J730) | E5: =D5-C5 | F5: =E5/D5
A8: CATEGORY WISE INVENTORY BREAKDOWN
A9: Category Group | B9: SKU Count | C9: Total Units | D9: Total Cost (PKR) | E9: Total Retail (PKR) | F9: Projected Margin (PKR) | G9: Margin %
A10: Store Assets & Equipment | B10: =COUNTIF('Inventory (Sorted)'!$C$4:$C$730, "Store Assets & Equipment") | C10: =SUMIF('Inventory (Sorted)'!$C$4:$C$730, "Store Assets & Equipment", 'Inventory (Sorted)'!$H$4:$H$730) | D10: =SUMIF('Inventory (Sorted)'!$C$4:$C$730, "Store Assets & Equipment", 'Inventory (Sorted)'!$I$4:$I$730) | E10: =SUMIF('Inventory (Sorted)'!$C$4:$C$730, "Store Assets & Equipment", 'Inventory (Sorted)'!$J$4:$J$730) | F10: =E10-D10 | G10: =IF(E10>0, F10/E10, 0)
A11: Beverages & Juices | B11: =COUNTIF('Inventory (Sorted)'!$C$4:$C$730, "Beverages & Juices") | C11: =SUMIF('Inventory (Sorted)'!$C$4:$C$730, "Beverages & Juices", 'Inventory (Sorted)'!$H$4:$H$730) | D11: =SUMIF('Inventory (Sorted)'!$C$4:$C$730, "Beverages & Juices", 'Inventory (Sorted)'!$I$4:$I$730) | E11: =SUMIF('Inventory (Sorted)'!$C$4:$C$730, "Beverages & Juices", 'Inventory (Sorted)'!$J$4:$J$730) | F11: =E11-D11 | G11: =IF(E11>0, F11/E11, 0)
A12: Cooking Oil & Ghee | B12: =COUNTIF('Inventory (Sorted)'!$C$4:$C$730, "Cooking Oil & Ghee") | C12: =SUMIF('Inventory (Sorted)'!$C$4:$C$730, "Cooking Oil & Ghee", 'Inventory (Sorted)'!$H$4:$H$730) | D12: =SUMIF('Inventory (Sorted)'!$C$4:$C$730, "Cooking Oil & Ghee", 'Inventory (Sorted)'!$I$4:$I$730) | E12: =SUMIF('Inventory (Sorted)'!$C$4:$C$730, "Cooking Oil & Ghee", 'Inventory (Sorted)'!$J$4:$J$730) | F12: =E12-D12 | G12: =IF(E12>0, F12/E12, 0)
A13: Rice & Staples | B13: =COUNTIF('Inventory (Sorted)'!$C$4:$C$730, "Rice & Staples") | C13: =SUMIF('Inventory (Sorted)'!$C$4:$C$730, "Rice & Staples", 'Inventory (Sorted)'!$H$4:$H$730) | D13: =SUMIF('Inventory (Sorted)'!$C$4:$C$730, "Rice & Staples", 'Inventory (Sorted)'!$I$4:$I$730) | E13: =SUMIF('Inventory (Sorted)'!$C$4:$C$730, "Rice & Staples", 'Inventory (Sorted)'!$J$4:$J$730) | F13: =E13-D13 | G13: =IF(E13>0, F13/E13, 0)
A14: Cigarettes & Tobacco | B14: =COUNTIF('Inventory (Sorted)'!$C$4:$C$730, "Cigarettes & Tobacco") | C14: =SUMIF('Inventory (Sorted)'!$C$4:$C$730, "Cigarettes & Tobacco", 'Inventory (Sorted)'!$H$4:$H$730) | D14: =SUMIF('Inventory (Sorted)'!$C$4:$C$730, "Cigarettes & Tobacco", 'Inventory (Sorted)'!$I$4:$I$730) | E14: =SUMIF('Inventory (Sorted)'!$C$4:$C$730, "Cigarettes & Tobacco", 'Inventory (Sorted)'!$J$4:$J$730) | F14: =E14-D14 | G14: =IF(E14>0, F14/E14, 0)
A15: Energy Drinks | B15: =COUNTIF('Inventory (Sorted)'!$C$4:$C$730, "Energy Drinks") | C15: =SUMIF('Inventory (Sorted)'!$C$4:$C$730, "Energy Drinks", 'Inventory (Sorted)'!$H$4:$H$730) | D15: =SUMIF('Inventory (Sorted)'!$C$4:$C$730, "Energy Drinks", 'Inventory (Sorted)'!$I$4:$I$730) | E15: =SUMIF('Inventory (Sorted)'!$C$4:$C$730, "Energy Drinks", 'Inventory (Sorted)'!$J$4:$J$730) | F15: =E15-D15 | G15: =IF(E15>0, F15/E15, 0)
A16: Baby Care | B16: =COUNTIF('Inventory (Sorted)'!$C$4:$C$730, "Baby Care") | C16: =SUMIF('Inventory (Sorted)'!$C$4:$C$730, "Baby Care", 'Inventory (Sorted)'!$H$4:$H$730) | D16: =SUMIF('Inventory (Sorted)'!$C$4:$C$730, "Baby Care", 'Inventory (Sorted)'!$I$4:$I$730) | E16: =SUMIF('Inventory (Sorted)'!$C$4:$C$730, "Baby Care", 'Inventory (Sorted)'!$J$4:$J$730) | F16: =E16-D16 | G16: =IF(E16>0, F16/E16, 0)
A17: Tea & Coffee | B17: =COUNTIF('Inventory (Sorted)'!$C$4:$C$730, "Tea & Coffee") | C17: =SUMIF('Inventory (Sorted)'!$C$4:$C$730, "Tea & Coffee", 'Inventory (Sorted)'!$H$4:$H$730) | D17: =SUMIF('Inventory (Sorted)'!$C$4:$C$730, "Tea & Coffee", 'Inventory (Sorted)'!$I$4:$I$730) | E17: =SUMIF('Inventory (Sorted)'!$C$4:$C$730, "Tea & Coffee", 'Inventory (Sorted)'!$J$4:$J$730) | F17: =E17-D17 | G17: =IF(E17>0, F17/E17, 0)
A18: Grains, Atta & Spices | B18: =COUNTIF('Inventory (Sorted)'!$C$4:$C$730, "Grains, Atta & Spices") | C18: =SUMIF('Inventory (Sorted)'!$C$4:$C$730, "Grains, Atta & Spices", 'Inventory (Sorted)'!$H$4:$H$730) | D18: =SUMIF('Inventory (Sorted)'!$C$4:$C$730, "Grains, Atta & Spices", 'Inventory (Sorted)'!$I$4:$I$730) | E18: =SUMIF('Inventory (Sorted)'!$C$4:$C$730, "Grains, Atta & Spices", 'Inventory (Sorted)'!$J$4:$J$730) | F18: =E18-D18 | G18: =IF(E18>0, F18/E18, 0)
A19: Biscuits & Bakery | B19: =COUNTIF('Inventory (Sorted)'!$C$4:$C$730, "Biscuits & Bakery") | C19: =SUMIF('Inventory (Sorted)'!$C$4:$C$730, "Biscuits & Bakery", 'Inventory (Sorted)'!$H$4:$H$730) | D19: =SUMIF('Inventory (Sorted)'!$C$4:$C$730, "Biscuits & Bakery", 'Inventory (Sorted)'!$I$4:$I$730) | E19: =SUMIF('Inventory (Sorted)'!$C$4:$C$730, "Biscuits & Bakery", 'Inventory (Sorted)'!$J$4:$J$730) | F19: =E19-D19 | G19: =IF(E19>0, F19/E19, 0)
A20: Item | B20: =COUNTIF('Inventory (Sorted)'!$C$4:$C$730, "Item") | C20: =SUMIF('Inventory (Sorted)'!$C$4:$C$730, "Item", 'Inventory (Sorted)'!$H$4:$H$730) | D20: =SUMIF('Inventory (Sorted)'!$C$4:$C$730, "Item", 'Inventory (Sorted)'!$I$4:$I$730) | E20: =SUMIF('Inventory (Sorted)'!$C$4:$C$730, "Item", 'Inventory (Sorted)'!$J$4:$J$730) | F20: =E20-D20 | G20: =IF(E20>0, F20/E20, 0)
A21: Personal Care & Hygiene | B21: =COUNTIF('Inventory (Sorted)'!$C$4:$C$730, "Personal Care & Hygiene") | C21: =SUMIF('Inventory (Sorted)'!$C$4:$C$730, "Personal Care & Hygiene", 'Inventory (Sorted)'!$H$4:$H$730) | D21: =SUMIF('Inventory (Sorted)'!$C$4:$C$730, "Personal Care & Hygiene", 'Inventory (Sorted)'!$I$4:$I$730) | E21: =SUMIF('Inventory (Sorted)'!$C$4:$C$730, "Personal Care & Hygiene", 'Inventory (Sorted)'!$J$4:$J$730) | F21: =E21-D21 | G21: =IF(E21>0, F21/E21, 0)
A22: Lentils & Pulses | B22: =COUNTIF('Inventory (Sorted)'!$C$4:$C$730, "Lentils & Pulses") | C22: =SUMIF('Inventory (Sorted)'!$C$4:$C$730, "Lentils & Pulses", 'Inventory (Sorted)'!$H$4:$H$730) | D22: =SUMIF('Inventory (Sorted)'!$C$4:$C$730, "Lentils & Pulses", 'Inventory (Sorted)'!$I$4:$I$730) | E22: =SUMIF('Inventory (Sorted)'!$C$4:$C$730, "Lentils & Pulses", 'Inventory (Sorted)'!$J$4:$J$730) | F22: =E22-D22 | G22: =IF(E22>0, F22/E22, 0)
A23: Cleaning & Household | B23: =COUNTIF('Inventory (Sorted)'!$C$4:$C$730, "Cleaning & Household") | C23: =SUMIF('Inventory (Sorted)'!$C$4:$C$730, "Cleaning & Household", 'Inventory (Sorted)'!$H$4:$H$730) | D23: =SUMIF('Inventory (Sorted)'!$C$4:$C$730, "Cleaning & Household", 'Inventory (Sorted)'!$I$4:$I$730) | E23: =SUMIF('Inventory (Sorted)'!$C$4:$C$730, "Cleaning & Household", 'Inventory (Sorted)'!$J$4:$J$730) | F23: =E23-D23 | G23: =IF(E23>0, F23/E23, 0)
A24: Cosmetics & Beauty | B24: =COUNTIF('Inventory (Sorted)'!$C$4:$C$730, "Cosmetics & Beauty") | C24: =SUMIF('Inventory (Sorted)'!$C$4:$C$730, "Cosmetics & Beauty", 'Inventory (Sorted)'!$H$4:$H$730) | D24: =SUMIF('Inventory (Sorted)'!$C$4:$C$730, "Cosmetics & Beauty", 'Inventory (Sorted)'!$I$4:$I$730) | E24: =SUMIF('Inventory (Sorted)'!$C$4:$C$730, "Cosmetics & Beauty", 'Inventory (Sorted)'!$J$4:$J$730) | F24: =E24-D24 | G24: =IF(E24>0, F24/E24, 0)
A25: Jam | B25: =COUNTIF('Inventory (Sorted)'!$C$4:$C$730, "Jam") | C25: =SUMIF('Inventory (Sorted)'!$C$4:$C$730, "Jam", 'Inventory (Sorted)'!$H$4:$H$730) | D25: =SUMIF('Inventory (Sorted)'!$C$4:$C$730, "Jam", 'Inventory (Sorted)'!$I$4:$I$730) | E25: =SUMIF('Inventory (Sorted)'!$C$4:$C$730, "Jam", 'Inventory (Sorted)'!$J$4:$J$730) | F25: =E25-D25 | G25: =IF(E25>0, F25/E25, 0)
A26: Tissues & Paper Goods | B26: =COUNTIF('Inventory (Sorted)'!$C$4:$C$730, "Tissues & Paper Goods") | C26: =SUMIF('Inventory (Sorted)'!$C$4:$C$730, "Tissues & Paper Goods", 'Inventory (Sorted)'!$H$4:$H$730) | D26: =SUMIF('Inventory (Sorted)'!$C$4:$C$730, "Tissues & Paper Goods", 'Inventory (Sorted)'!$I$4:$I$730) | E26: =SUMIF('Inventory (Sorted)'!$C$4:$C$730, "Tissues & Paper Goods", 'Inventory (Sorted)'!$J$4:$J$730) | F26: =E26-D26 | G26: =IF(E26>0, F26/E26, 0)
A27: Milk | B27: =COUNTIF('Inventory (Sorted)'!$C$4:$C$730, "Milk") | C27: =SUMIF('Inventory (Sorted)'!$C$4:$C$730, "Milk", 'Inventory (Sorted)'!$H$4:$H$730) | D27: =SUMIF('Inventory (Sorted)'!$C$4:$C$730, "Milk", 'Inventory (Sorted)'!$I$4:$I$730) | E27: =SUMIF('Inventory (Sorted)'!$C$4:$C$730, "Milk", 'Inventory (Sorted)'!$J$4:$J$730) | F27: =E27-D27 | G27: =IF(E27>0, F27/E27, 0)
A28: Tomato Paste | B28: =COUNTIF('Inventory (Sorted)'!$C$4:$C$730, "Tomato Paste") | C28: =SUMIF('Inventory (Sorted)'!$C$4:$C$730, "Tomato Paste", 'Inventory (Sorted)'!$H$4:$H$730) | D28: =SUMIF('Inventory (Sorted)'!$C$4:$C$730, "Tomato Paste", 'Inventory (Sorted)'!$I$4:$I$730) | E28: =SUMIF('Inventory (Sorted)'!$C$4:$C$730, "Tomato Paste", 'Inventory (Sorted)'!$J$4:$J$730) | F28: =E28-D28 | G28: =IF(E28>0, F28/E28, 0)
A29: Snacks & Nimko | B29: =COUNTIF('Inventory (Sorted)'!$C$4:$C$730, "Snacks & Nimko") | C29: =SUMIF('Inventory (Sorted)'!$C$4:$C$730, "Snacks & Nimko", 'Inventory (Sorted)'!$H$4:$H$730) | D29: =SUMIF('Inventory (Sorted)'!$C$4:$C$730, "Snacks & Nimko", 'Inventory (Sorted)'!$I$4:$I$730) | E29: =SUMIF('Inventory (Sorted)'!$C$4:$C$730, "Snacks & Nimko", 'Inventory (Sorted)'!$J$4:$J$730) | F29: =E29-D29 | G29: =IF(E29>0, F29/E29, 0)
A30: Laundry & Detergents | B30: =COUNTIF('Inventory (Sorted)'!$C$4:$C$730, "Laundry & Detergents") | C30: =SUMIF('Inventory (Sorted)'!$C$4:$C$730, "Laundry & Detergents", 'Inventory (Sorted)'!$H$4:$H$730) | D30: =SUMIF('Inventory (Sorted)'!$C$4:$C$730, "Laundry & Detergents", 'Inventory (Sorted)'!$I$4:$I$730) | E30: =SUMIF('Inventory (Sorted)'!$C$4:$C$730, "Laundry & Detergents", 'Inventory (Sorted)'!$J$4:$J$730) | F30: =E30-D30 | G30: =IF(E30>0, F30/E30, 0)
A31: Nutrition | B31: =COUNTIF('Inventory (Sorted)'!$C$4:$C$730, "Nutrition") | C31: =SUMIF('Inventory (Sorted)'!$C$4:$C$730, "Nutrition", 'Inventory (Sorted)'!$H$4:$H$730) | D31: =SUMIF('Inventory (Sorted)'!$C$4:$C$730, "Nutrition", 'Inventory (Sorted)'!$I$4:$I$730) | E31: =SUMIF('Inventory (Sorted)'!$C$4:$C$730, "Nutrition", 'Inventory (Sorted)'!$J$4:$J$730) | F31: =E31-D31 | G31: =IF(E31>0, F31/E31, 0)
A32: Test | B32: =COUNTIF('Inventory (Sorted)'!$C$4:$C$730, "Test") | C32: =SUMIF('Inventory (Sorted)'!$C$4:$C$730, "Test", 'Inventory (Sorted)'!$H$4:$H$730) | D32: =SUMIF('Inventory (Sorted)'!$C$4:$C$730, "Test", 'Inventory (Sorted)'!$I$4:$I$730) | E32: =SUMIF('Inventory (Sorted)'!$C$4:$C$730, "Test", 'Inventory (Sorted)'!$J$4:$J$730) | F32: =E32-D32 | G32: =IF(E32>0, F32/E32, 0)
A33: Perfumes & Body Sprays | B33: =COUNTIF('Inventory (Sorted)'!$C$4:$C$730, "Perfumes & Body Sprays") | C33: =SUMIF('Inventory (Sorted)'!$C$4:$C$730, "Perfumes & Body Sprays", 'Inventory (Sorted)'!$H$4:$H$730) | D33: =SUMIF('Inventory (Sorted)'!$C$4:$C$730, "Perfumes & Body Sprays", 'Inventory (Sorted)'!$I$4:$I$730) | E33: =SUMIF('Inventory (Sorted)'!$C$4:$C$730, "Perfumes & Body Sprays", 'Inventory (Sorted)'!$J$4:$J$730) | F33: =E33-D33 | G33: =IF(E33>0, F33/E33, 0)
A34: Ice Cream | B34: =COUNTIF('Inventory (Sorted)'!$C$4:$C$730, "Ice Cream") | C34: =SUMIF('Inventory (Sorted)'!$C$4:$C$730, "Ice Cream", 'Inventory (Sorted)'!$H$4:$H$730) | D34: =SUMIF('Inventory (Sorted)'!$C$4:$C$730, "Ice Cream", 'Inventory (Sorted)'!$I$4:$I$730) | E34: =SUMIF('Inventory (Sorted)'!$C$4:$C$730, "Ice Cream", 'Inventory (Sorted)'!$J$4:$J$730) | F34: =E34-D34 | G34: =IF(E34>0, F34/E34, 0)
A35: Noodles | B35: =COUNTIF('Inventory (Sorted)'!$C$4:$C$730, "Noodles") | C35: =SUMIF('Inventory (Sorted)'!$C$4:$C$730, "Noodles", 'Inventory (Sorted)'!$H$4:$H$730) | D35: =SUMIF('Inventory (Sorted)'!$C$4:$C$730, "Noodles", 'Inventory (Sorted)'!$I$4:$I$730) | E35: =SUMIF('Inventory (Sorted)'!$C$4:$C$730, "Noodles", 'Inventory (Sorted)'!$J$4:$J$730) | F35: =E35-D35 | G35: =IF(E35>0, F35/E35, 0)
A36: Dry Fruit | B36: =COUNTIF('Inventory (Sorted)'!$C$4:$C$730, "Dry Fruit") | C36: =SUMIF('Inventory (Sorted)'!$C$4:$C$730, "Dry Fruit", 'Inventory (Sorted)'!$H$4:$H$730) | D36: =SUMIF('Inventory (Sorted)'!$C$4:$C$730, "Dry Fruit", 'Inventory (Sorted)'!$I$4:$I$730) | E36: =SUMIF('Inventory (Sorted)'!$C$4:$C$730, "Dry Fruit", 'Inventory (Sorted)'!$J$4:$J$730) | F36: =E36-D36 | G36: =IF(E36>0, F36/E36, 0)
A37: Stain Remover | B37: =COUNTIF('Inventory (Sorted)'!$C$4:$C$730, "Stain Remover") | C37: =SUMIF('Inventory (Sorted)'!$C$4:$C$730, "Stain Remover", 'Inventory (Sorted)'!$H$4:$H$730) | D37: =SUMIF('Inventory (Sorted)'!$C$4:$C$730, "Stain Remover", 'Inventory (Sorted)'!$I$4:$I$730) | E37: =SUMIF('Inventory (Sorted)'!$C$4:$C$730, "Stain Remover", 'Inventory (Sorted)'!$J$4:$J$730) | F37: =E37-D37 | G37: =IF(E37>0, F37/E37, 0)
A38: Black Peper | B38: =COUNTIF('Inventory (Sorted)'!$C$4:$C$730, "Black Peper") | C38: =SUMIF('Inventory (Sorted)'!$C$4:$C$730, "Black Peper", 'Inventory (Sorted)'!$H$4:$H$730) | D38: =SUMIF('Inventory (Sorted)'!$C$4:$C$730, "Black Peper", 'Inventory (Sorted)'!$I$4:$I$730) | E38: =SUMIF('Inventory (Sorted)'!$C$4:$C$730, "Black Peper", 'Inventory (Sorted)'!$J$4:$J$730) | F38: =E38-D38 | G38: =IF(E38>0, F38/E38, 0)
A39: Cream | B39: =COUNTIF('Inventory (Sorted)'!$C$4:$C$730, "Cream") | C39: =SUMIF('Inventory (Sorted)'!$C$4:$C$730, "Cream", 'Inventory (Sorted)'!$H$4:$H$730) | D39: =SUMIF('Inventory (Sorted)'!$C$4:$C$730, "Cream", 'Inventory (Sorted)'!$I$4:$I$730) | E39: =SUMIF('Inventory (Sorted)'!$C$4:$C$730, "Cream", 'Inventory (Sorted)'!$J$4:$J$730) | F39: =E39-D39 | G39: =IF(E39>0, F39/E39, 0)
A40: Water | B40: =COUNTIF('Inventory (Sorted)'!$C$4:$C$730, "Water") | C40: =SUMIF('Inventory (Sorted)'!$C$4:$C$730, "Water", 'Inventory (Sorted)'!$H$4:$H$730) | D40: =SUMIF('Inventory (Sorted)'!$C$4:$C$730, "Water", 'Inventory (Sorted)'!$I$4:$I$730) | E40: =SUMIF('Inventory (Sorted)'!$C$4:$C$730, "Water", 'Inventory (Sorted)'!$J$4:$J$730) | F40: =E40-D40 | G40: =IF(E40>0, F40/E40, 0)
A41: Razor | B41: =COUNTIF('Inventory (Sorted)'!$C$4:$C$730, "Razor") | C41: =SUMIF('Inventory (Sorted)'!$C$4:$C$730, "Razor", 'Inventory (Sorted)'!$H$4:$H$730) | D41: =SUMIF('Inventory (Sorted)'!$C$4:$C$730, "Razor", 'Inventory (Sorted)'!$I$4:$I$730) | E41: =SUMIF('Inventory (Sorted)'!$C$4:$C$730, "Razor", 'Inventory (Sorted)'!$J$4:$J$730) | F41: =E41-D41 | G41: =IF(E41>0, F41/E41, 0)
A42: Chewing Gum & Mints | B42: =COUNTIF('Inventory (Sorted)'!$C$4:$C$730, "Chewing Gum & Mints") | C42: =SUMIF('Inventory (Sorted)'!$C$4:$C$730, "Chewing Gum & Mints", 'Inventory (Sorted)'!$H$4:$H$730) | D42: =SUMIF('Inventory (Sorted)'!$C$4:$C$730, "Chewing Gum & Mints", 'Inventory (Sorted)'!$I$4:$I$730) | E42: =SUMIF('Inventory (Sorted)'!$C$4:$C$730, "Chewing Gum & Mints", 'Inventory (Sorted)'!$J$4:$J$730) | F42: =E42-D42 | G42: =IF(E42>0, F42/E42, 0)
A43: Macroni | B43: =COUNTIF('Inventory (Sorted)'!$C$4:$C$730, "Macroni") | C43: =SUMIF('Inventory (Sorted)'!$C$4:$C$730, "Macroni", 'Inventory (Sorted)'!$H$4:$H$730) | D43: =SUMIF('Inventory (Sorted)'!$C$4:$C$730, "Macroni", 'Inventory (Sorted)'!$I$4:$I$730) | E43: =SUMIF('Inventory (Sorted)'!$C$4:$C$730, "Macroni", 'Inventory (Sorted)'!$J$4:$J$730) | F43: =E43-D43 | G43: =IF(E43>0, F43/E43, 0)
...

Sheet Inventory (Sorted)
A1: COMPLETE STORE INVENTORY (SORTED BY CATEGORY)
A3: Barcode / SKU | B3: Product Name | C3: Category Group | D3: Original Category | E3: Purchase Price | F3: Sale Price | G3: Unit Margin | H3: Stock Qty | I3: Total Cost Value | J3: Total Retail Value | K3: Stock Status | L3: Date Added
A4: 1425738481454 | B4: BLACK TIGER ACID | C4: Acid | D4: Acid | E4: 47 | F4: 80 | G4: =F4-E4 | H4: 10 | I4: =E4*H4 | J4: =F4*H4 | K4: =IF(H4<=0, "Out of Stock", IF(H4<=5, "Low Stock", "In Stock")) | L4: 2025-07-14 06:15 PM
A5: 8964003538491 | B5: CORAL AIR FRESHNER BERRY | C5: Air Freshner | D5: Air Freshner | E5: 210 | F5: 350 | G5: =F5-E5 | H5: 3 | I5: =E5*H5 | J5: =F5*H5 | K5: =IF(H5<=0, "Out of Stock", IF(H5<=5, "Low Stock", "In Stock")) | L5: 2025-07-15 12:05 PM
A6: 8964003538675 | B6: CORAL AIR FRESHNER BLACK ICE | C6: Air Freshner | D6: Air Freshner | E6: 210 | F6: 350 | G6: =F6-E6 | H6: 2 | I6: =E6*H6 | J6: =F6*H6 | K6: =IF(H6<=0, "Out of Stock", IF(H6<=5, "Low Stock", "In Stock")) | L6: 2025-07-15 12:01 PM
A7: 8964003538453 | B7: CORAL AIR FRESHNER OCEAN | C7: Air Freshner | D7: Air Freshner | E7: 210 | F7: 350 | G7: =F7-E7 | H7: 12 | I7: =E7*H7 | J7: =F7*H7 | K7: =IF(H7<=0, "Out of Stock", IF(H7<=5, "Low Stock", "In Stock")) | L7: 2025-07-15 12:02 PM
A8: 8964003538507 | B8: CORAL AIR FRESHNER ORANGE | C8: Air Freshner | D8: Air Freshner | E8: 210 | F8: 350 | G8: =F8-E8 | H8: 4 | I8: =E8*H8 | J8: =F8*H8 | K8: =IF(H8<=0, "Out of Stock", IF(H8<=5, "Low Stock", "In Stock")) | L8: 2025-07-15 12:03 PM
A9: 8964003538477 | B9: CORAL AIR FRESHNER | C9: Air Fresshner | D9: Air Fresshner | E9: 210 | F9: 350 | G9: =F9-E9 | H9: 3 | I9: =E9*H9 | J9: =F9*H9 | K9: =IF(H9<=0, "Out of Stock", IF(H9<=5, "Low Stock", "In Stock")) | L9: 2025-07-15 12:00 PM
A10: 8991111109121 | B10: JOHANSONS BABY POWDER | C10: Baby Care | D10: Baby Powder | E10: 155 | F10: 200 | G10: =F10-E10 | H10: 11 | I10: =E10*H10 | J10: =F10*H10 | K10: =IF(H10<=0, "Out of Stock", IF(H10<=5, "Low Stock", "In Stock")) | L10: 2025-07-14 03:46 PM
A11: 8063304010009 | B11: COOL SOFT BABY WIPES | C11: Baby Care | D11: Baby Wipes | E11: 380 | F11: 450 | G11: =F11-E11 | H11: 13 | I11: =E11*H11 | J11: =F11*H11 | K11: =IF(H11<=0, "Out of Stock", IF(H11<=5, "Low Stock", "In Stock")) | L11: 2025-07-13 03:45 PM
A12: 8993560027544 | B12: DETTOL BABY WIPES | C12: Baby Care | D12: Baby Wipes | E12: 150 | F12: 250 | G12: =F12-E12 | H12: 8 | I12: =E12*H12 | J12: =F12*H12 | K12: =IF(H12<=0, "Out of Stock", IF(H12<=5, "Low Stock", "In Stock")) | L12: 2025-07-13 03:52 PM
A13: 5559666888873 | B13: JEEP BABY WIPES | C13: Baby Care | D13: Baby Wipes | E13: 150 | F13: 250 | G13: =F13-E13 | H13: 7 | I13: =E13*H13 | J13: =F13*H13 | K13: =IF(H13<=0, "Out of Stock", IF(H13<=5, "Low Stock", "In Stock")) | L13: 2025-07-13 03:47 PM
A14: 257896548349 | B14: RAHAT BABY WIPES | C14: Baby Care | D14: Baby Wipes | E14: 100 | F14: 150 | G14: =F14-E14 | H14: 23 | I14: =E14*H14 | J14: =F14*H14 | K14: =IF(H14<=0, "Out of Stock", IF(H14<=5, "Low Stock", "In Stock")) | L14: 2025-07-13 03:37 PM
A15: 5126511533457 | B15: ROCKET BABY WIPES | C15: Baby Care | D15: Baby Wipes | E15: 108 | F15: 160 | G15: =F15-E15 | H15: 25 | I15: =E15*H15 | J15: =F15*H15 | K15: =IF(H15<=0, "Out of Stock", IF(H15<=5, "Low Stock", "In Stock")) | L15: 2025-07-13 03:37 PM
... A730: 6936965445683 | B730: CORRECTION PEN WHITENER | C730: Whitener | D730: Whitener | E730: 70 | F730: 100 | G730: =F730-E730 | H730: 18 | I730: =E730*H730 | J730: =F730*H730 | K730: =IF(H730<=0, "Out of Stock", IF(H730<=5, "Low Stock", "In Stock")) | L730: 2025-07-13 06:42 PM
B731: TOTALS | H731: =SUM(H4:H730) | I731: =SUM(I4:I730) | J731: =SUM(J4:J730)
